<?xml version="1.0" ?>
<!-- =================================================================================== -->
<!-- |    This document was autogenerated by xacro from /home/swimming/dev_ws/src/AIDL_ip010_lecture/ip010_gazebo/urdf/ip010.urdf.xacro | -->
<!-- |    EDITING THIS FILE BY HAND IS NOT RECOMMENDED                                 | -->
<!-- =================================================================================== -->
<robot name="ip010">
  <gazebo>
    <plugin filename="libgazebo_ros_control.so" name="control"/>
  </gazebo>
  <gazebo reference="base_link">
    <material>Gazebo/DarkGrey</material>
    <mu1>0.01</mu1>
    <mu2>0.01</mu2>
    <selfCollide>true</selfCollide>
    <gravity>true</gravity>
  </gazebo>
  <gazebo reference="front_ballcaster">
    <material>Gazebo/DarkGrey</material>
    <mu1>0.1</mu1>
    <mu2>0.1</mu2>
    <selfCollide>true</selfCollide>
    <gravity>true</gravity>
  </gazebo>
  <gazebo reference="center_lidar">
    <material>Gazebo/Silver</material>
    <mu1>0.2</mu1>
    <mu2>0.2</mu2>
    <selfCollide>true</selfCollide>
  </gazebo>
  <gazebo reference="l_rear_wheel">
    <material>Gazebo/FlatBlack</material>
    <mu1>100000.0</mu1>
    <mu2>100000.0</mu2>
    <selfCollide>true</selfCollide>
  </gazebo>
  <gazebo reference="r_rear_wheel">
    <material>Gazebo/FlatBlack</material>
    <mu1>100000.0</mu1>
    <mu2>100000.0</mu2>
    <selfCollide>true</selfCollide>
  </gazebo>
  <gazebo reference="front_camera">
    <material>Gazebo/LightBlueLaser</material>
    <selfCollide>true</selfCollide>
  </gazebo>
  <gazebo>
    <plugin filename="libgazebo_ros_joint_state_publisher.so" name="joint_states">
      <joint_name>l_rear_wheel_joint</joint_name>
      <joint_name>r_rear_wheel_joint</joint_name>
    </plugin>
    <plugin filename="libgazebo_ros_diff_drive.so" name="diff_drive">
      <update_rate>50</update_rate>
      <left_joint>l_rear_wheel_joint</left_joint>
      <right_joint>r_rear_wheel_joint</right_joint>
      <wheel_separation>0.194</wheel_separation>
      <wheel_diameter>0.07</wheel_diameter>
      <max_wheel_torque>500</max_wheel_torque>
      <max_wheel_acceleration>10.0</max_wheel_acceleration>
      <command_topic>cmd_vel</command_topic>
      <publish_odom>1</publish_odom>
      <publish_odom_tf>1</publish_odom_tf>
      <publish_wheel_tf>0</publish_wheel_tf>
      <odometry_topic>odom</odometry_topic>
      <odometry_frame>odom</odometry_frame>
      <robot_base_frame>base_footprint</robot_base_frame>
    </plugin>
  </gazebo>
  <gazebo reference="center_lidar">
    <sensor name="lidar" type="ray">
      <!-- Rplidar A1 Specification Referred -->
      <!-- https://www.slamtec.com/en/Lidar/A1Spec -->
      <ray>
        <scan>
          <horizontal>
            <samples>360</samples>
            <resolution>1.000000</resolution>
            <min_angle>-3.14159</min_angle>
            <max_angle>3.14159</max_angle>
          </horizontal>
        </scan>
        <range>
          <min>0.15</min>
          <max>12.0</max>
          <resolution>0.015</resolution>
        </range>
        <noise>
          <type>gaussian</type>
          <mean>0.0</mean>
          <stddev>0.0001</stddev>
        </noise>
      </ray>
      <pose>0 0 0 0 0 0</pose>
      <always_on>true</always_on>
      <visualize>false</visualize>
      <update_rate>5.5</update_rate>
      <plugin filename="libgazebo_ros_ray_sensor.so" name="scan">
        <ros>
          <remapping>~/out:=scan</remapping>
        </ros>
        <output_type>sensor_msgs/LaserScan</output_type>
        <frame_name>center_lidar</frame_name>
      </plugin>
    </sensor>
  </gazebo>
  <gazebo reference="front_camera">
    <sensor name="sensor_name" type="camera">
      <update_rate>30</update_rate>
      <visualize>true</visualize>
      <always_on>1</always_on>
      <camera name="front_camera">
        <horizontal_fov>1.3962634</horizontal_fov>
        <image>
          <width>1280</width>
          <height>720</height>
          <format>R8G8B8</format>
        </image>
        <clip>
          <near>0.02</near>
          <far>300</far>
        </clip>
        <noise>
          <type>gaussian</type>
          <mean>0.0</mean>
          <!-- <stddev>0.007</stddev> -->
          <stddev>0.00007</stddev>
        </noise>
      </camera>
      <plugin filename="libgazebo_ros_camera.so" name="camera_controller">
        <!-- Change namespace, camera name and topics so:
               * Images are published to: /custom_ns/custom_camera/custom_image
               * Camera info is published to: /custom_ns/custom_camera/custom_info 
          -->
        <ros>
          <!-- <namespace>custom_ns</namespace> -->
          <argument>image_raw:=image_raw</argument>
          <argument>camera_info:=camera_info</argument>
        </ros>
        <hack_baseline>0.07</hack_baseline>
      </plugin>
    </sensor>
  </gazebo>
  <link name="base_footprint"/>
  <link name="base_link">
    <inertial>
      <origin rpy="0 0 0" xyz="-0.000385245156391871 -0.000529111847711822 0.0653719962073427"/>
      <mass value="1.22178095373168"/>
      <inertia ixx="0.00627094203593516" ixy="3.03044325621882E-05" ixz="0.000574351883582968" iyy="0.00807367810614195" iyz="-9.26695226612923E-06" izz="0.0136241544527254"/>
    </inertial>
    <visual>
      <origin rpy="0 0 0" xyz="0 0 0"/>
      <geometry>
        <mesh filename="/home/swimming/dev_ws/install/ip010_description/share/ip010_description/meshes/base_link.STL"/>
      </geometry>
      <material name="">
        <color rgba="0.43921568627451 0.43921568627451 0.43921568627451 1"/>
      </material>
    </visual>
    <collision>
      <origin rpy="0 0 0" xyz="0 0 0"/>
      <geometry>
        <mesh filename="/home/swimming/dev_ws/install/ip010_description/share/ip010_description/meshes/base_link.STL"/>
      </geometry>
    </collision>
  </link>
  <joint name="base_link_joint" type="fixed">
    <origin rpy="0 0 0" xyz="0 0 0"/>
    <parent link="base_footprint"/>
    <child link="base_link"/>
  </joint>
  <link name="l_rear_wheel">
    <inertial>
      <origin rpy="0 0 0" xyz="-0.000276941065544781 -0.0201570866836339 0.000883513372436709"/>
      <mass value="0.115203108377027"/>
      <inertia ixx="3.76597824097435E-05" ixy="4.04398415924187E-09" ixz="-7.54861656391369E-09" iyy="6.30867844960361E-05" iyz="-1.25464212048792E-08" izz="3.7679837109253E-05"/>
    </inertial>
    <visual>
      <origin rpy="0 0 0" xyz="0 0 0"/>
      <geometry>
        <mesh filename="/home/swimming/dev_ws/install/ip010_description/share/ip010_description/meshes/l_rear_wheel.STL"/>
      </geometry>
      <material name="">
        <color rgba="0.792156862745098 0.819607843137255 0.933333333333333 1"/>
      </material>
    </visual>
    <collision>
      <origin rpy="0 0 0" xyz="0 0 0"/>
      <geometry>
        <mesh filename="/home/swimming/dev_ws/install/ip010_description/share/ip010_description/meshes/l_rear_wheel.STL"/>
      </geometry>
    </collision>
  </link>
  <joint name="l_rear_wheel_joint" type="continuous">
    <origin rpy="0 0 0" xyz="-0.0945003880978201 0.11 0.0350001078633251"/>
    <parent link="base_link"/>
    <child link="l_rear_wheel"/>
    <axis xyz="0 1 0"/>
  </joint>
  <link name="r_rear_wheel">
    <inertial>
      <origin rpy="0 0 0" xyz="-0.000279144572909285 0.020157085967068 0.000882819590486731"/>
      <mass value="0.115203107255679"/>
      <inertia ixx="3.76592750408973E-05" ixy="-3.87283160946061E-09" ixz="-6.82269545443431E-09" iyy="6.30867844954026E-05" iyz="1.26003043153597E-08" izz="3.76803444665559E-05"/>
    </inertial>
    <visual>
      <origin rpy="0 0 0" xyz="0 0 0"/>
      <geometry>
        <mesh filename="/home/swimming/dev_ws/install/ip010_description/share/ip010_description/meshes/r_rear_wheel.STL"/>
      </geometry>
      <material name="">
        <color rgba="0.792156862745098 0.819607843137255 0.933333333333333 1"/>
      </material>
    </visual>
    <collision>
      <origin rpy="0 0 0" xyz="0 0 0"/>
      <geometry>
        <mesh filename="/home/swimming/dev_ws/install/ip010_description/share/ip010_description/meshes/r_rear_wheel.STL"/>
      </geometry>
    </collision>
  </link>
  <joint name="r_rear_wheel_joint" type="continuous">
    <origin rpy="0 0 0" xyz="-0.0944997436888031 -0.11 0.035000310739568"/>
    <parent link="base_link"/>
    <child link="r_rear_wheel"/>
    <axis xyz="0 1 0"/>
  </joint>
  <link name="center_lidar">
    <inertial>
      <origin rpy="0 0 0" xyz="0.00745008536583489 -0.000328953238206021 -0.0193022240939329"/>
      <mass value="0.118327011339017"/>
      <inertia ixx="3.75663376249697E-05" ixy="-1.04736915416129E-07" ixz="-4.28429420894516E-07" iyy="4.21124856419297E-05" iyz="9.24636939164067E-09" izz="4.6508188174353E-05"/>
    </inertial>
    <visual>
      <origin rpy="0 0 0" xyz="0 0 0"/>
      <geometry>
        <mesh filename="/home/swimming/dev_ws/install/ip010_description/share/ip010_description/meshes/center_lidar.STL"/>
      </geometry>
      <material name="">
        <color rgba="0.752941176470588 0.752941176470588 0.752941176470588 1"/>
      </material>
    </visual>
    <collision>
      <origin rpy="0 0 0" xyz="0 0 0"/>
      <geometry>
        <mesh filename="/home/swimming/dev_ws/install/ip010_description/share/ip010_description/meshes/center_lidar.STL"/>
      </geometry>
    </collision>
  </link>
  <joint name="center_lidar_joint" type="fixed">
    <origin rpy="0 0 0" xyz="-0.031999999999999 0 0.108300000000198"/>
    <parent link="base_link"/>
    <child link="center_lidar"/>
    <!-- <axis xyz="0 0 -1" /> -->
  </joint>
  <link name="front_camera">
    <inertial>
      <origin rpy="0 0 0" xyz="-0.00497560083527254 1.16551733542192E-18 -0.00156090309940154"/>
      <mass value="0.000679586163770489"/>
      <inertia ixx="5.37689116983891E-08" ixy="7.2963616570538E-26" ixz="-5.56265931483273E-10" iyy="2.8597907949626E-08" iyz="-3.19266396131941E-24" izz="2.75239156052624E-08"/>
    </inertial>
    <visual>
      <origin rpy="0 0 0" xyz="0 0 0"/>
      <geometry>
        <mesh filename="/home/swimming/dev_ws/install/ip010_description/share/ip010_description/meshes/front_camera.STL"/>
      </geometry>
      <material name="">
        <color rgba="0.792156862745098 0.819607843137255 0.933333333333333 1"/>
      </material>
    </visual>
    <collision>
      <origin rpy="0 0 0" xyz="0 0 0"/>
      <geometry>
        <mesh filename="/home/swimming/dev_ws/install/ip010_description/share/ip010_description/meshes/front_camera.STL"/>
      </geometry>
    </collision>
  </link>
  <joint name="front_camera_joint" type="fixed">
    <origin rpy="0 0 0" xyz="0.141847512071907 -0.000215421199800007 0.0680000000002"/>
    <parent link="base_link"/>
    <child link="front_camera"/>
    <!-- <axis xyz="1 0 0" /> -->
  </joint>
</robot>
