<?xml version="1.0" ?>
<!-- =================================================================================== -->
<!-- |    This document was autogenerated by xacro from /home/kimsooyoung/ros2_ws/src/AIDL_ip010_lecture/ip010_gazebo/urdf/ip010_description.urdf.xacro | -->
<!-- |    EDITING THIS FILE BY HAND IS NOT RECOMMENDED                                 | -->
<!-- =================================================================================== -->
<robot name="ip010">
  <gazebo>
    <plugin filename="libgazebo_ros_control.so" name="control"/>
  </gazebo>
  <gazebo reference="base_link">
    <material>Gazebo/DarkGrey</material>
    <mu1>0.01</mu1>
    <mu2>0.01</mu2>
    <selfCollide>true</selfCollide>
    <gravity>true</gravity>
  </gazebo>
  <gazebo reference="front_ballcaster">
    <material>Gazebo/DarkGrey</material>
    <mu1>0.1</mu1>
    <mu2>0.1</mu2>
    <selfCollide>true</selfCollide>
    <gravity>true</gravity>
  </gazebo>
  <gazebo reference="center_lidar">
    <material>Gazebo/Silver</material>
    <mu1>0.2</mu1>
    <mu2>0.2</mu2>
    <selfCollide>true</selfCollide>
  </gazebo>
  <gazebo reference="l_rear_wheel">
    <material>Gazebo/FlatBlack</material>
    <mu1>100000.0</mu1>
    <mu2>100000.0</mu2>
    <selfCollide>true</selfCollide>
  </gazebo>
  <gazebo reference="r_rear_wheel">
    <material>Gazebo/FlatBlack</material>
    <mu1>100000.0</mu1>
    <mu2>100000.0</mu2>
    <selfCollide>true</selfCollide>
  </gazebo>
  <gazebo reference="front_camera">
    <material>Gazebo/LightBlueLaser</material>
    <selfCollide>true</selfCollide>
  </gazebo>
  <gazebo>
    <plugin filename="libgazebo_ros_joint_state_publisher.so" name="joint_states">
      <joint_name>l_rear_wheel_joint</joint_name>
      <joint_name>r_rear_wheel_joint</joint_name>
    </plugin>
    <plugin filename="libgazebo_ros_diff_drive.so" name="diff_drive">
      <update_rate>50</update_rate>
      <left_joint>l_rear_wheel_joint</left_joint>
      <right_joint>r_rear_wheel_joint</right_joint>
      <wheel_separation>0.194</wheel_separation>
      <wheel_diameter>0.07</wheel_diameter>
      <max_wheel_torque>500</max_wheel_torque>
      <max_wheel_acceleration>10.0</max_wheel_acceleration>
      <command_topic>cmd_vel</command_topic>
      <publish_odom>1</publish_odom>
      <publish_odom_tf>1</publish_odom_tf>
      <publish_wheel_tf>0</publish_wheel_tf>
      <odometry_topic>odom</odometry_topic>
      <odometry_frame>odom</odometry_frame>
      <robot_base_frame>base_footprint</robot_base_frame>
    </plugin>
  </gazebo>
  <gazebo reference="center_lidar">
    <sensor name="lidar" type="ray">
      <!-- Rplidar A1 Specification Referred -->
      <!-- https://www.slamtec.com/en/Lidar/A1Spec -->
      <ray>
        <scan>
          <horizontal>
            <samples>360</samples>
            <resolution>1.000000</resolution>
            <min_angle>-3.14159</min_angle>
            <max_angle>3.14159</max_angle>
          </horizontal>
        </scan>
        <range>
          <min>0.15</min>
          <max>12.0</max>
          <resolution>0.015</resolution>
        </range>
        <noise>
          <type>gaussian</type>
          <mean>0.0</mean>
          <stddev>0.0001</stddev>
        </noise>
      </ray>
      <pose>0 0 0 0 0 0</pose>
      <always_on>true</always_on>
      <visualize>false</visualize>
      <update_rate>5.5</update_rate>
      <plugin filename="libgazebo_ros_ray_sensor.so" name="scan">
        <ros>
          <remapping>~/out:=scan</remapping>
        </ros>
        <output_type>sensor_msgs/LaserScan</output_type>
        <frame_name>center_lidar</frame_name>
      </plugin>
    </sensor>
  </gazebo>
  <gazebo reference="front_camera">
    <sensor name="sensor_name" type="camera">
      <update_rate>30</update_rate>
      <visualize>true</visualize>
      <always_on>1</always_on>
      <camera name="front_camera">
        <horizontal_fov>1.3962634</horizontal_fov>
        <image>
          <width>1280</width>
          <height>720</height>
          <format>R8G8B8</format>
        </image>
        <clip>
          <near>0.02</near>
          <far>300</far>
        </clip>
        <noise>
          <type>gaussian</type>
          <mean>0.0</mean>
          <!-- <stddev>0.007</stddev> -->
          <stddev>0.00007</stddev>
        </noise>
      </camera>
      <plugin filename="libgazebo_ros_camera.so" name="camera_controller">
        <!-- Change namespace, camera name and topics so:
               * Images are published to: /custom_ns/custom_camera/custom_image
               * Camera info is published to: /custom_ns/custom_camera/custom_info 
          -->
        <ros>
          <!-- <namespace>custom_ns</namespace> -->
          <argument>image_raw:=image_raw</argument>
          <argument>camera_info:=camera_info</argument>
        </ros>
        <hack_baseline>0.07</hack_baseline>
      </plugin>
    </sensor>
  </gazebo>
  <link name="base_footprint"/>
  <link name="base_link">
    <inertial>
      <origin rpy="0 0 0" xyz="-0.010365884133191 -0.000576778488747551 0.0698064146454796"/>
      <mass value="1.12083938753469"/>
      <inertia ixx="0.00625390309602125" ixy="3.03054612238855E-05" ixz="0.000573867658783163" iyy="0.0080987780933677" iyz="-9.26731016583709E-06" izz="0.0136845094087104"/>
    </inertial>
    <visual>
      <origin rpy="0 0 0" xyz="0 0 0"/>
      <geometry>
        <mesh filename="/home/kimsooyoung/ros2_ws/install/ip010_description/share/ip010_description/meshes/base_link.STL"/>
      </geometry>
      <material name="">
        <color rgba="0.43921568627451 0.43921568627451 0.43921568627451 1"/>
      </material>
    </visual>
    <collision>
      <origin rpy="0 0 0" xyz="0 0 0"/>
      <geometry>
        <mesh filename="/home/kimsooyoung/ros2_ws/install/ip010_description/share/ip010_description/meshes/base_link.STL"/>
      </geometry>
    </collision>
  </link>
  <joint name="base_link_joint" type="fixed">
    <origin rpy="0 0 0" xyz="0 0 0"/>
    <parent link="base_footprint"/>
    <child link="base_link"/>
  </joint>
  <link name="l_rear_wheel">
    <inertial>
      <origin rpy="0 0 0" xyz="0.000416078291276656 -0.020157083474482 0.000827146053683048"/>
      <mass value="0.115203103310497"/>
      <inertia ixx="3.76619524598008E-05" ixy="-5.82867896238268E-09" ixz="9.78735956742376E-09" iyy="6.30867844857624E-05" iyz="-1.1823408757557E-08" izz="3.76776670177481E-05"/>
    </inertial>
    <visual>
      <origin rpy="0 0 0" xyz="0 0 0"/>
      <geometry>
        <mesh filename="/home/kimsooyoung/ros2_ws/install/ip010_description/share/ip010_description/meshes/l_rear_wheel.STL"/>
      </geometry>
      <material name="">
        <color rgba="0.792156862745098 0.819607843137255 0.933333333333333 1"/>
      </material>
    </visual>
    <collision>
      <origin rpy="0 0 0" xyz="0 0 0"/>
      <geometry>
        <mesh filename="/home/kimsooyoung/ros2_ws/install/ip010_description/share/ip010_description/meshes/l_rear_wheel.STL"/>
      </geometry>
    </collision>
  </link>
  <joint name="l_rear_wheel_joint" type="continuous">
    <origin rpy="0 0 0" xyz="-0.0945002035940863 0.11 0.0350003475684688"/>
    <parent link="base_link"/>
    <child link="l_rear_wheel"/>
    <axis xyz="0 1 0"/>
  </joint>
  <link name="r_rear_wheel">
    <inertial>
      <origin rpy="0 0 0" xyz="0.000414013270580993 0.0201570841374701 0.000828181653934248"/>
      <mass value="0.115203104348033"/>
      <inertia ixx="3.76626622310331E-05" ixy="5.98907546101305E-09" ixz="1.0317087954516E-08" iyy="6.30867844864224E-05" iyz="1.17429752615601E-08" izz="3.76769572572774E-05"/>
    </inertial>
    <visual>
      <origin rpy="0 0 0" xyz="0 0 0"/>
      <geometry>
        <mesh filename="/home/kimsooyoung/ros2_ws/install/ip010_description/share/ip010_description/meshes/r_rear_wheel.STL"/>
      </geometry>
      <material name="">
        <color rgba="0.792156862745098 0.819607843137255 0.933333333333333 1"/>
      </material>
    </visual>
    <collision>
      <origin rpy="0 0 0" xyz="0 0 0"/>
      <geometry>
        <mesh filename="/home/kimsooyoung/ros2_ws/install/ip010_description/share/ip010_description/meshes/r_rear_wheel.STL"/>
      </geometry>
    </collision>
  </link>
  <joint name="r_rear_wheel_joint" type="continuous">
    <origin rpy="0 0 0" xyz="-0.0944995996831282 -0.11 0.0350000447264209"/>
    <parent link="base_link"/>
    <child link="r_rear_wheel"/>
    <axis xyz="0 1 0"/>
  </joint>
  <link name="front_ballcaster">
    <inertial>
      <origin rpy="0 0 0" xyz="2.32896466001442E-10 1.88369250417493E-10 0.00930627232022497"/>
      <mass value="0.0209327830608877"/>
      <inertia ixx="1.48299880678707E-06" ixy="-1.7043650171883E-13" ixz="-7.73616758546749E-15" iyy="1.31107957877558E-06" iyz="-6.17056111578677E-15" izz="1.88921846876978E-06"/>
    </inertial>
    <visual>
      <origin rpy="0 0 0" xyz="0 0 0"/>
      <geometry>
        <mesh filename="/home/kimsooyoung/ros2_ws/install/ip010_description/share/ip010_description/meshes/front_ballcaster.STL"/>
      </geometry>
      <material name="">
        <color rgba="0.752941176470588 0.752941176470588 0.752941176470588 1"/>
      </material>
    </visual>
    <collision>
      <origin rpy="0 0 0" xyz="0 0 0"/>
      <geometry>
        <mesh filename="/home/kimsooyoung/ros2_ws/install/ip010_description/share/ip010_description/meshes/front_ballcaster.STL"/>
      </geometry>
    </collision>
  </link>
  <joint name="front_ballcaster_joint" type="fixed">
    <origin rpy="0 0 0" xyz="0.0879999994802632 0 0.000999753890741178"/>
    <parent link="base_link"/>
    <child link="front_ballcaster"/>
    <!-- <axis xyz="0 0 -1" /> -->
  </joint>
  <link name="center_lidar">
    <inertial>
      <origin rpy="0 0 0" xyz="0.00755339223480704 -0.00027896548418537 -0.0300022240938231"/>
      <mass value="0.118327011344308"/>
      <inertia ixx="3.75663376269071E-05" ixy="-1.04736914369223E-07" ixz="-4.28429420760351E-07" iyy="4.21124856446319E-05" iyz="9.24636933962534E-09" izz="4.65081881789805E-05"/>
    </inertial>
    <visual>
      <origin rpy="0 0 0" xyz="0 0 0"/>
      <geometry>
        <mesh filename="/home/kimsooyoung/ros2_ws/install/ip010_description/share/ip010_description/meshes/center_lidar.STL"/>
      </geometry>
      <material name="">
        <color rgba="0.752941176470588 0.752941176470588 0.752941176470588 1"/>
      </material>
    </visual>
    <collision>
      <origin rpy="0 0 0" xyz="0 0 0"/>
      <geometry>
        <mesh filename="/home/kimsooyoung/ros2_ws/install/ip010_description/share/ip010_description/meshes/center_lidar.STL"/>
      </geometry>
    </collision>
  </link>
  <joint name="center_lidar_joint" type="fixed">
    <origin rpy="0 0 0" xyz="-0.0321033068699902 -4.99877536184437E-05 0.119000000000201"/>
    <parent link="base_link"/>
    <child link="center_lidar"/>
    <!-- <axis xyz="0 0 -1" /> -->
  </joint>
  <link name="front_camera">
    <inertial>
      <origin rpy="0 0 0" xyz="-0.00497560083527254 5.6920614055489E-19 -0.00156090309940154"/>
      <mass value="0.000679586163770489"/>
      <inertia ixx="5.37689116983891E-08" ixy="6.67253526693495E-26" ixz="-5.56265931483273E-10" iyy="2.8597907949626E-08" iyz="-3.19408275992568E-24" izz="2.75239156052624E-08"/>
    </inertial>
    <visual>
      <origin rpy="0 0 0" xyz="0 0 0"/>
      <geometry>
        <mesh filename="/home/kimsooyoung/ros2_ws/install/ip010_description/share/ip010_description/meshes/front_camera.STL"/>
      </geometry>
      <material name="">
        <color rgba="0.792156862745098 0.819607843137255 0.933333333333333 1"/>
      </material>
    </visual>
    <collision>
      <origin rpy="0 0 0" xyz="0 0 0"/>
      <geometry>
        <mesh filename="/home/kimsooyoung/ros2_ws/install/ip010_description/share/ip010_description/meshes/front_camera.STL"/>
      </geometry>
    </collision>
  </link>
  <joint name="front_camera_joint" type="fixed">
    <origin rpy="0 0 0" xyz="0.141847512071907 -0.000215421199799998 0.0680000000002"/>
    <parent link="base_link"/>
    <child link="front_camera"/>
  </joint>
</robot>
